nohup: ignoring input
INFO:     Will watch for changes in these directories: ['/home/ubuntu/devhacks/backend']
INFO:     Uvicorn running on http://0.0.0.0:8000 (Press CTRL+C to quit)
INFO:     Started reloader process [41224] using WatchFiles
Process SpawnProcess-1:
Traceback (most recent call last):
  File "/usr/lib/python3.12/multiprocessing/process.py", line 314, in _bootstrap
    self.run()
  File "/usr/lib/python3.12/multiprocessing/process.py", line 108, in run
    self._target(*self._args, **self._kwargs)
  File "/home/ubuntu/devhacks/venv/lib/python3.12/site-packages/uvicorn/_subprocess.py", line 76, in subprocess_started
    target(sockets=sockets)
  File "/home/ubuntu/devhacks/venv/lib/python3.12/site-packages/uvicorn/server.py", line 61, in run
    return asyncio.run(self.serve(sockets=sockets))
           ^^^^^^^^^^^^^^^^^^^^^^^^^^^^^^^^^^^^^^^^
  File "/usr/lib/python3.12/asyncio/runners.py", line 194, in run
    return runner.run(main)
           ^^^^^^^^^^^^^^^^
  File "/usr/lib/python3.12/asyncio/runners.py", line 118, in run
    return self._loop.run_until_complete(task)
           ^^^^^^^^^^^^^^^^^^^^^^^^^^^^^^^^^^^
  File "uvloop/loop.pyx", line 1518, in uvloop.loop.Loop.run_until_complete
  File "/home/ubuntu/devhacks/venv/lib/python3.12/site-packages/uvicorn/server.py", line 68, in serve
    config.load()
  File "/home/ubuntu/devhacks/venv/lib/python3.12/site-packages/uvicorn/config.py", line 467, in load
    self.loaded_app = import_from_string(self.app)
                      ^^^^^^^^^^^^^^^^^^^^^^^^^^^^
  File "/home/ubuntu/devhacks/venv/lib/python3.12/site-packages/uvicorn/importer.py", line 24, in import_from_string
    raise exc from None
  File "/home/ubuntu/devhacks/venv/lib/python3.12/site-packages/uvicorn/importer.py", line 21, in import_from_string
    module = importlib.import_module(module_str)
             ^^^^^^^^^^^^^^^^^^^^^^^^^^^^^^^^^^^
  File "/usr/lib/python3.12/importlib/__init__.py", line 90, in import_module
    return _bootstrap._gcd_import(name[level:], package, level)
           ^^^^^^^^^^^^^^^^^^^^^^^^^^^^^^^^^^^^^^^^^^^^^^^^^^^^
  File "<frozen importlib._bootstrap>", line 1387, in _gcd_import
  File "<frozen importlib._bootstrap>", line 1360, in _find_and_load
  File "<frozen importlib._bootstrap>", line 1331, in _find_and_load_unlocked
  File "<frozen importlib._bootstrap>", line 935, in _load_unlocked
  File "<frozen importlib._bootstrap_external>", line 995, in exec_module
  File "<frozen importlib._bootstrap>", line 488, in _call_with_frames_removed
  File "/home/ubuntu/devhacks/backend/main.py", line 3, in <module>
    from routes import router
  File "/home/ubuntu/devhacks/backend/routes.py", line 5, in <module>
    import backend.companies as companies
ModuleNotFoundError: No module named 'backend'
WARNING:  WatchFiles detected changes in 'routes.py'. Reloading...
INFO:     Started server process [41560]
INFO:     Waiting for application startup.
INFO:     Application startup complete.
WARNING:  WatchFiles detected changes in 'routes.py'. Reloading...
INFO:     Shutting down
INFO:     Waiting for application shutdown.
INFO:     Application shutdown complete.
INFO:     Finished server process [41560]
INFO:     Started server process [42097]
INFO:     Waiting for application startup.
INFO:     Application startup complete.
WARNING:  WatchFiles detected changes in 'models.py'. Reloading...
INFO:     Shutting down
INFO:     Waiting for application shutdown.
INFO:     Application shutdown complete.
INFO:     Finished server process [42097]
Process SpawnProcess-4:
Traceback (most recent call last):
  File "/home/ubuntu/devhacks/venv/lib/python3.12/site-packages/sqlalchemy/engine/base.py", line 1969, in _exec_single_context
    self.dialect.do_execute(
  File "/home/ubuntu/devhacks/venv/lib/python3.12/site-packages/sqlalchemy/engine/default.py", line 922, in do_execute
    cursor.execute(statement, parameters)
psycopg2.errors.UniqueViolation: duplicate key value violates unique constraint "pg_class_relname_nsp_index"
DETAIL:  Key (relname, relnamespace)=(chat_messages_id_seq, 2200) already exists.


The above exception was the direct cause of the following exception:

Traceback (most recent call last):
  File "/usr/lib/python3.12/multiprocessing/process.py", line 314, in _bootstrap
    self.run()
  File "/usr/lib/python3.12/multiprocessing/process.py", line 108, in run
    self._target(*self._args, **self._kwargs)
  File "/home/ubuntu/devhacks/venv/lib/python3.12/site-packages/uvicorn/_subprocess.py", line 76, in subprocess_started
    target(sockets=sockets)
  File "/home/ubuntu/devhacks/venv/lib/python3.12/site-packages/uvicorn/server.py", line 61, in run
    return asyncio.run(self.serve(sockets=sockets))
           ^^^^^^^^^^^^^^^^^^^^^^^^^^^^^^^^^^^^^^^^
  File "/usr/lib/python3.12/asyncio/runners.py", line 194, in run
    return runner.run(main)
           ^^^^^^^^^^^^^^^^
  File "/usr/lib/python3.12/asyncio/runners.py", line 118, in run
    return self._loop.run_until_complete(task)
           ^^^^^^^^^^^^^^^^^^^^^^^^^^^^^^^^^^^
  File "uvloop/loop.pyx", line 1518, in uvloop.loop.Loop.run_until_complete
  File "/home/ubuntu/devhacks/venv/lib/python3.12/site-packages/uvicorn/server.py", line 68, in serve
    config.load()
  File "/home/ubuntu/devhacks/venv/lib/python3.12/site-packages/uvicorn/config.py", line 467, in load
    self.loaded_app = import_from_string(self.app)
                      ^^^^^^^^^^^^^^^^^^^^^^^^^^^^
  File "/home/ubuntu/devhacks/venv/lib/python3.12/site-packages/uvicorn/importer.py", line 21, in import_from_string
    module = importlib.import_module(module_str)
             ^^^^^^^^^^^^^^^^^^^^^^^^^^^^^^^^^^^
  File "/usr/lib/python3.12/importlib/__init__.py", line 90, in import_module
    return _bootstrap._gcd_import(name[level:], package, level)
           ^^^^^^^^^^^^^^^^^^^^^^^^^^^^^^^^^^^^^^^^^^^^^^^^^^^^
  File "<frozen importlib._bootstrap>", line 1387, in _gcd_import
  File "<frozen importlib._bootstrap>", line 1360, in _find_and_load
  File "<frozen importlib._bootstrap>", line 1331, in _find_and_load_unlocked
  File "<frozen importlib._bootstrap>", line 935, in _load_unlocked
  File "<frozen importlib._bootstrap_external>", line 995, in exec_module
  File "<frozen importlib._bootstrap>", line 488, in _call_with_frames_removed
  File "/home/ubuntu/devhacks/backend/main.py", line 8, in <module>
    Base.metadata.create_all(bind=engine)
  File "/home/ubuntu/devhacks/venv/lib/python3.12/site-packages/sqlalchemy/sql/schema.py", line 5828, in create_all
    bind._run_ddl_visitor(
  File "/home/ubuntu/devhacks/venv/lib/python3.12/site-packages/sqlalchemy/engine/base.py", line 3243, in _run_ddl_visitor
    conn._run_ddl_visitor(visitorcallable, element, **kwargs)
  File "/home/ubuntu/devhacks/venv/lib/python3.12/site-packages/sqlalchemy/engine/base.py", line 2447, in _run_ddl_visitor
    visitorcallable(self.dialect, self, **kwargs).traverse_single(element)
  File "/home/ubuntu/devhacks/venv/lib/python3.12/site-packages/sqlalchemy/sql/visitors.py", line 671, in traverse_single
    return meth(obj, **kw)
           ^^^^^^^^^^^^^^^
  File "/home/ubuntu/devhacks/venv/lib/python3.12/site-packages/sqlalchemy/sql/ddl.py", line 919, in visit_metadata
    self.traverse_single(
  File "/home/ubuntu/devhacks/venv/lib/python3.12/site-packages/sqlalchemy/sql/visitors.py", line 671, in traverse_single
    return meth(obj, **kw)
           ^^^^^^^^^^^^^^^
  File "/home/ubuntu/devhacks/venv/lib/python3.12/site-packages/sqlalchemy/sql/ddl.py", line 957, in visit_table
    )._invoke_with(self.connection)
      ^^^^^^^^^^^^^^^^^^^^^^^^^^^^^
  File "/home/ubuntu/devhacks/venv/lib/python3.12/site-packages/sqlalchemy/sql/ddl.py", line 315, in _invoke_with
    return bind.execute(self)
           ^^^^^^^^^^^^^^^^^^
  File "/home/ubuntu/devhacks/venv/lib/python3.12/site-packages/sqlalchemy/engine/base.py", line 1416, in execute
    return meth(
           ^^^^^
  File "/home/ubuntu/devhacks/venv/lib/python3.12/site-packages/sqlalchemy/sql/ddl.py", line 181, in _execute_on_connection
    return connection._execute_ddl(
           ^^^^^^^^^^^^^^^^^^^^^^^^
  File "/home/ubuntu/devhacks/venv/lib/python3.12/site-packages/sqlalchemy/engine/base.py", line 1528, in _execute_ddl
    ret = self._execute_context(
          ^^^^^^^^^^^^^^^^^^^^^^
  File "/home/ubuntu/devhacks/venv/lib/python3.12/site-packages/sqlalchemy/engine/base.py", line 1848, in _execute_context
    return self._exec_single_context(
           ^^^^^^^^^^^^^^^^^^^^^^^^^^
  File "/home/ubuntu/devhacks/venv/lib/python3.12/site-packages/sqlalchemy/engine/base.py", line 1988, in _exec_single_context
    self._handle_dbapi_exception(
  File "/home/ubuntu/devhacks/venv/lib/python3.12/site-packages/sqlalchemy/engine/base.py", line 2343, in _handle_dbapi_exception
    raise sqlalchemy_exception.with_traceback(exc_info[2]) from e
  File "/home/ubuntu/devhacks/venv/lib/python3.12/site-packages/sqlalchemy/engine/base.py", line 1969, in _exec_single_context
    self.dialect.do_execute(
  File "/home/ubuntu/devhacks/venv/lib/python3.12/site-packages/sqlalchemy/engine/default.py", line 922, in do_execute
    cursor.execute(statement, parameters)
sqlalchemy.exc.IntegrityError: (psycopg2.errors.UniqueViolation) duplicate key value violates unique constraint "pg_class_relname_nsp_index"
DETAIL:  Key (relname, relnamespace)=(chat_messages_id_seq, 2200) already exists.

[SQL: 
CREATE TABLE chat_messages (
	id SERIAL NOT NULL, 
	message TEXT NOT NULL, 
	sender VARCHAR(255) NOT NULL, 
	created_at TIMESTAMP WITH TIME ZONE DEFAULT now(), 
	PRIMARY KEY (id)
)

]
(Background on this error at: https://sqlalche.me/e/20/gkpj)
WARNING:  WatchFiles detected changes in 'schemas.py'. Reloading...
INFO:     Started server process [52558]
INFO:     Waiting for application startup.
INFO:     Application startup complete.
WARNING:  WatchFiles detected changes in 'companies.py'. Reloading...
INFO:     Shutting down
INFO:     Waiting for application shutdown.
INFO:     Application shutdown complete.
INFO:     Finished server process [52558]
INFO:     Started server process [52683]
INFO:     Waiting for application startup.
INFO:     Application startup complete.
WARNING:  WatchFiles detected changes in 'routes.py'. Reloading...
INFO:     Shutting down
INFO:     Waiting for application shutdown.
INFO:     Application shutdown complete.
INFO:     Finished server process [52683]
Process SpawnProcess-7:
Traceback (most recent call last):
  File "/usr/lib/python3.12/multiprocessing/process.py", line 314, in _bootstrap
    self.run()
  File "/usr/lib/python3.12/multiprocessing/process.py", line 108, in run
    self._target(*self._args, **self._kwargs)
  File "/home/ubuntu/devhacks/venv/lib/python3.12/site-packages/uvicorn/_subprocess.py", line 76, in subprocess_started
    target(sockets=sockets)
  File "/home/ubuntu/devhacks/venv/lib/python3.12/site-packages/uvicorn/server.py", line 61, in run
    return asyncio.run(self.serve(sockets=sockets))
           ^^^^^^^^^^^^^^^^^^^^^^^^^^^^^^^^^^^^^^^^
  File "/usr/lib/python3.12/asyncio/runners.py", line 194, in run
    return runner.run(main)
           ^^^^^^^^^^^^^^^^
  File "/usr/lib/python3.12/asyncio/runners.py", line 118, in run
    return self._loop.run_until_complete(task)
           ^^^^^^^^^^^^^^^^^^^^^^^^^^^^^^^^^^^
  File "uvloop/loop.pyx", line 1518, in uvloop.loop.Loop.run_until_complete
  File "/home/ubuntu/devhacks/venv/lib/python3.12/site-packages/uvicorn/server.py", line 68, in serve
    config.load()
  File "/home/ubuntu/devhacks/venv/lib/python3.12/site-packages/uvicorn/config.py", line 467, in load
    self.loaded_app = import_from_string(self.app)
                      ^^^^^^^^^^^^^^^^^^^^^^^^^^^^
  File "/home/ubuntu/devhacks/venv/lib/python3.12/site-packages/uvicorn/importer.py", line 24, in import_from_string
    raise exc from None
  File "/home/ubuntu/devhacks/venv/lib/python3.12/site-packages/uvicorn/importer.py", line 21, in import_from_string
    module = importlib.import_module(module_str)
             ^^^^^^^^^^^^^^^^^^^^^^^^^^^^^^^^^^^
  File "/usr/lib/python3.12/importlib/__init__.py", line 90, in import_module
    return _bootstrap._gcd_import(name[level:], package, level)
           ^^^^^^^^^^^^^^^^^^^^^^^^^^^^^^^^^^^^^^^^^^^^^^^^^^^^
  File "<frozen importlib._bootstrap>", line 1387, in _gcd_import
  File "<frozen importlib._bootstrap>", line 1360, in _find_and_load
  File "<frozen importlib._bootstrap>", line 1331, in _find_and_load_unlocked
  File "<frozen importlib._bootstrap>", line 935, in _load_unlocked
  File "<frozen importlib._bootstrap_external>", line 995, in exec_module
  File "<frozen importlib._bootstrap>", line 488, in _call_with_frames_removed
  File "/home/ubuntu/devhacks/backend/main.py", line 3, in <module>
    from routes import router
  File "/home/ubuntu/devhacks/backend/routes.py", line 5, in <module>
    import crud
ModuleNotFoundError: No module named 'crud'
WARNING:  WatchFiles detected changes in 'routes.py'. Reloading...
INFO:     Started server process [55075]
INFO:     Waiting for application startup.
INFO:     Application startup complete.
WARNING:  WatchFiles detected changes in 'routes.py'. Reloading...
INFO:     Shutting down
INFO:     Waiting for application shutdown.
INFO:     Application shutdown complete.
INFO:     Finished server process [55075]
INFO:     Started server process [55288]
INFO:     Waiting for application startup.
INFO:     Application startup complete.
INFO:     Shutting down
INFO:     Waiting for application shutdown.
INFO:     Application shutdown complete.
INFO:     Finished server process [55288]
INFO:     Stopping reloader process [41224]
